## 关于`Promise.all`的问题

最近写业务代码遇到一个问题，就是写异步代码的时候，某个流程的逻辑依赖前面的异步输出，而前面有好几个异步操作，于是用的`Promise.all`并行执行异步逻辑。
然而却发现矛盾的情况：异步输出的结果还没存储到对应的变量，后面就已经执行了。仔细一看，发现是前面并行的异步操作中有一个出错了。。。。。而我在`Promise.all`
后面加了一个catch的操作处理了错误（仅仅是输出，没有中断后面的代码执行）。于是异步操作提前结束，执行了后面的代码，也就是其中一个并行子任务的错误导致了主
代码没有等待其它子任务的执行完毕就执行了后面的代码。


## 为什么会遇到这个问题
这里主要关键是我在`Promise.all`返回的`Promise`对象加了一个catch操作，而没有中断后面的执行逻辑导致的，当时我的思路是为了处理一下非中断的错误而添加的catch
（这里的业务是我把未登录后台返回的需要鉴权的回包当成错误抛出了，此时应该直接跳过不做处理，所以要加catch处理）。于是我把catch转移到了实际要处理的子异步任务的
`Promise`里面，不然错误的中断影响到其它子任务的执行。
